2025-05-16 14:30:00,206 ERROR scheduler Exception in Enqueue Events for Site library.localhost
Traceback (most recent call last):
  File "/Users/shahin/frappe-demo/env/lib/python3.11/site-packages/pymysql/connections.py", line 649, in connect
    sock = socket.create_connection(
           ^^^^^^^^^^^^^^^^^^^^^^^^^
  File "/opt/homebrew/Cellar/python@3.11/3.11.12/Frameworks/Python.framework/Versions/3.11/lib/python3.11/socket.py", line 863, in create_connection
    raise exceptions[0]
  File "/opt/homebrew/Cellar/python@3.11/3.11.12/Frameworks/Python.framework/Versions/3.11/lib/python3.11/socket.py", line 848, in create_connection
    sock.connect(sa)
ConnectionRefusedError: [Errno 61] Connection refused

During handling of the above exception, another exception occurred:

Traceback (most recent call last):
  File "/Users/shahin/frappe-demo/apps/frappe/frappe/utils/scheduler.py", line 117, in enqueue_events_for_site
    if is_scheduler_inactive():
       ^^^^^^^^^^^^^^^^^^^^^^^
  File "/Users/shahin/frappe-demo/apps/frappe/frappe/utils/scheduler.py", line 161, in is_scheduler_inactive
    if is_scheduler_disabled(verbose=verbose):
       ^^^^^^^^^^^^^^^^^^^^^^^^^^^^^^^^^^^^^^
  File "/Users/shahin/frappe-demo/apps/frappe/frappe/utils/scheduler.py", line 174, in is_scheduler_disabled
    frappe.db.get_single_value("System Settings", "enable_scheduler")
  File "/Users/shahin/frappe-demo/apps/frappe/frappe/database/database.py", line 884, in get_single_value
    ).run()
      ^^^^^
  File "/Users/shahin/frappe-demo/apps/frappe/frappe/query_builder/utils.py", line 85, in execute_query
    result = frappe.db.sql(query, params, *args, **kwargs)  # nosemgrep
             ^^^^^^^^^^^^^^^^^^^^^^^^^^^^^^^^^^^^^^^^^^^^^
  File "/Users/shahin/frappe-demo/apps/frappe/frappe/database/database.py", line 237, in sql
    self.connect()
  File "/Users/shahin/frappe-demo/apps/frappe/frappe/database/database.py", line 135, in connect
    self.get_connection()
  File "/Users/shahin/frappe-demo/apps/frappe/frappe/database/mariadb/database.py", line 106, in get_connection
    conn = self._get_connection()
           ^^^^^^^^^^^^^^^^^^^^^^
  File "/Users/shahin/frappe-demo/apps/frappe/frappe/database/mariadb/database.py", line 112, in _get_connection
    return self.create_connection()
           ^^^^^^^^^^^^^^^^^^^^^^^^
  File "/Users/shahin/frappe-demo/apps/frappe/frappe/database/mariadb/database.py", line 115, in create_connection
    return pymysql.connect(**self.get_connection_settings())
           ^^^^^^^^^^^^^^^^^^^^^^^^^^^^^^^^^^^^^^^^^^^^^^^^^
  File "/Users/shahin/frappe-demo/env/lib/python3.11/site-packages/pymysql/connections.py", line 361, in __init__
    self.connect()
  File "/Users/shahin/frappe-demo/env/lib/python3.11/site-packages/pymysql/connections.py", line 716, in connect
    raise exc
pymysql.err.OperationalError: (2003, "Can't connect to MySQL server on '127.0.0.1' ([Errno 61] Connection refused)")
2025-05-16 14:34:00,230 ERROR scheduler Exception in Enqueue Events for Site library.localhost
Traceback (most recent call last):
  File "/Users/shahin/frappe-demo/env/lib/python3.11/site-packages/pymysql/connections.py", line 649, in connect
    sock = socket.create_connection(
           ^^^^^^^^^^^^^^^^^^^^^^^^^
  File "/opt/homebrew/Cellar/python@3.11/3.11.12/Frameworks/Python.framework/Versions/3.11/lib/python3.11/socket.py", line 863, in create_connection
    raise exceptions[0]
  File "/opt/homebrew/Cellar/python@3.11/3.11.12/Frameworks/Python.framework/Versions/3.11/lib/python3.11/socket.py", line 848, in create_connection
    sock.connect(sa)
ConnectionRefusedError: [Errno 61] Connection refused

During handling of the above exception, another exception occurred:

Traceback (most recent call last):
  File "/Users/shahin/frappe-demo/apps/frappe/frappe/utils/scheduler.py", line 117, in enqueue_events_for_site
    if is_scheduler_inactive():
       ^^^^^^^^^^^^^^^^^^^^^^^
  File "/Users/shahin/frappe-demo/apps/frappe/frappe/utils/scheduler.py", line 161, in is_scheduler_inactive
    if is_scheduler_disabled(verbose=verbose):
       ^^^^^^^^^^^^^^^^^^^^^^^^^^^^^^^^^^^^^^
  File "/Users/shahin/frappe-demo/apps/frappe/frappe/utils/scheduler.py", line 174, in is_scheduler_disabled
    frappe.db.get_single_value("System Settings", "enable_scheduler")
  File "/Users/shahin/frappe-demo/apps/frappe/frappe/database/database.py", line 884, in get_single_value
    ).run()
      ^^^^^
  File "/Users/shahin/frappe-demo/apps/frappe/frappe/query_builder/utils.py", line 85, in execute_query
    result = frappe.db.sql(query, params, *args, **kwargs)  # nosemgrep
             ^^^^^^^^^^^^^^^^^^^^^^^^^^^^^^^^^^^^^^^^^^^^^
  File "/Users/shahin/frappe-demo/apps/frappe/frappe/database/database.py", line 237, in sql
    self.connect()
  File "/Users/shahin/frappe-demo/apps/frappe/frappe/database/database.py", line 135, in connect
    self.get_connection()
  File "/Users/shahin/frappe-demo/apps/frappe/frappe/database/mariadb/database.py", line 106, in get_connection
    conn = self._get_connection()
           ^^^^^^^^^^^^^^^^^^^^^^
  File "/Users/shahin/frappe-demo/apps/frappe/frappe/database/mariadb/database.py", line 112, in _get_connection
    return self.create_connection()
           ^^^^^^^^^^^^^^^^^^^^^^^^
  File "/Users/shahin/frappe-demo/apps/frappe/frappe/database/mariadb/database.py", line 115, in create_connection
    return pymysql.connect(**self.get_connection_settings())
           ^^^^^^^^^^^^^^^^^^^^^^^^^^^^^^^^^^^^^^^^^^^^^^^^^
  File "/Users/shahin/frappe-demo/env/lib/python3.11/site-packages/pymysql/connections.py", line 361, in __init__
    self.connect()
  File "/Users/shahin/frappe-demo/env/lib/python3.11/site-packages/pymysql/connections.py", line 716, in connect
    raise exc
pymysql.err.OperationalError: (2003, "Can't connect to MySQL server on '127.0.0.1' ([Errno 61] Connection refused)")
2025-05-16 14:38:43,662 ERROR scheduler Exception in Enqueue Events for Site library.localhost
Traceback (most recent call last):
  File "/Users/shahin/frappe-demo/env/lib/python3.11/site-packages/pymysql/connections.py", line 649, in connect
    sock = socket.create_connection(
           ^^^^^^^^^^^^^^^^^^^^^^^^^
  File "/opt/homebrew/Cellar/python@3.11/3.11.12/Frameworks/Python.framework/Versions/3.11/lib/python3.11/socket.py", line 863, in create_connection
    raise exceptions[0]
  File "/opt/homebrew/Cellar/python@3.11/3.11.12/Frameworks/Python.framework/Versions/3.11/lib/python3.11/socket.py", line 848, in create_connection
    sock.connect(sa)
ConnectionRefusedError: [Errno 61] Connection refused

During handling of the above exception, another exception occurred:

Traceback (most recent call last):
  File "/Users/shahin/frappe-demo/apps/frappe/frappe/utils/scheduler.py", line 117, in enqueue_events_for_site
    if is_scheduler_inactive():
       ^^^^^^^^^^^^^^^^^^^^^^^
  File "/Users/shahin/frappe-demo/apps/frappe/frappe/utils/scheduler.py", line 161, in is_scheduler_inactive
    if is_scheduler_disabled(verbose=verbose):
       ^^^^^^^^^^^^^^^^^^^^^^^^^^^^^^^^^^^^^^
  File "/Users/shahin/frappe-demo/apps/frappe/frappe/utils/scheduler.py", line 174, in is_scheduler_disabled
    frappe.db.get_single_value("System Settings", "enable_scheduler")
  File "/Users/shahin/frappe-demo/apps/frappe/frappe/database/database.py", line 884, in get_single_value
    ).run()
      ^^^^^
  File "/Users/shahin/frappe-demo/apps/frappe/frappe/query_builder/utils.py", line 85, in execute_query
    result = frappe.db.sql(query, params, *args, **kwargs)  # nosemgrep
             ^^^^^^^^^^^^^^^^^^^^^^^^^^^^^^^^^^^^^^^^^^^^^
  File "/Users/shahin/frappe-demo/apps/frappe/frappe/database/database.py", line 237, in sql
    self.connect()
  File "/Users/shahin/frappe-demo/apps/frappe/frappe/database/database.py", line 135, in connect
    self.get_connection()
  File "/Users/shahin/frappe-demo/apps/frappe/frappe/database/mariadb/database.py", line 106, in get_connection
    conn = self._get_connection()
           ^^^^^^^^^^^^^^^^^^^^^^
  File "/Users/shahin/frappe-demo/apps/frappe/frappe/database/mariadb/database.py", line 112, in _get_connection
    return self.create_connection()
           ^^^^^^^^^^^^^^^^^^^^^^^^
  File "/Users/shahin/frappe-demo/apps/frappe/frappe/database/mariadb/database.py", line 115, in create_connection
    return pymysql.connect(**self.get_connection_settings())
           ^^^^^^^^^^^^^^^^^^^^^^^^^^^^^^^^^^^^^^^^^^^^^^^^^
  File "/Users/shahin/frappe-demo/env/lib/python3.11/site-packages/pymysql/connections.py", line 361, in __init__
    self.connect()
  File "/Users/shahin/frappe-demo/env/lib/python3.11/site-packages/pymysql/connections.py", line 716, in connect
    raise exc
pymysql.err.OperationalError: (2003, "Can't connect to MySQL server on '127.0.0.1' ([Errno 61] Connection refused)")
2025-05-16 14:42:00,680 ERROR scheduler Exception in Enqueue Events for Site library.localhost
Traceback (most recent call last):
  File "/Users/shahin/frappe-demo/env/lib/python3.11/site-packages/pymysql/connections.py", line 649, in connect
    sock = socket.create_connection(
           ^^^^^^^^^^^^^^^^^^^^^^^^^
  File "/opt/homebrew/Cellar/python@3.11/3.11.12/Frameworks/Python.framework/Versions/3.11/lib/python3.11/socket.py", line 863, in create_connection
    raise exceptions[0]
  File "/opt/homebrew/Cellar/python@3.11/3.11.12/Frameworks/Python.framework/Versions/3.11/lib/python3.11/socket.py", line 848, in create_connection
    sock.connect(sa)
ConnectionRefusedError: [Errno 61] Connection refused

During handling of the above exception, another exception occurred:

Traceback (most recent call last):
  File "/Users/shahin/frappe-demo/apps/frappe/frappe/utils/scheduler.py", line 117, in enqueue_events_for_site
    if is_scheduler_inactive():
       ^^^^^^^^^^^^^^^^^^^^^^^
  File "/Users/shahin/frappe-demo/apps/frappe/frappe/utils/scheduler.py", line 161, in is_scheduler_inactive
    if is_scheduler_disabled(verbose=verbose):
       ^^^^^^^^^^^^^^^^^^^^^^^^^^^^^^^^^^^^^^
  File "/Users/shahin/frappe-demo/apps/frappe/frappe/utils/scheduler.py", line 174, in is_scheduler_disabled
    frappe.db.get_single_value("System Settings", "enable_scheduler")
  File "/Users/shahin/frappe-demo/apps/frappe/frappe/database/database.py", line 884, in get_single_value
    ).run()
      ^^^^^
  File "/Users/shahin/frappe-demo/apps/frappe/frappe/query_builder/utils.py", line 85, in execute_query
    result = frappe.db.sql(query, params, *args, **kwargs)  # nosemgrep
             ^^^^^^^^^^^^^^^^^^^^^^^^^^^^^^^^^^^^^^^^^^^^^
  File "/Users/shahin/frappe-demo/apps/frappe/frappe/database/database.py", line 237, in sql
    self.connect()
  File "/Users/shahin/frappe-demo/apps/frappe/frappe/database/database.py", line 135, in connect
    self.get_connection()
  File "/Users/shahin/frappe-demo/apps/frappe/frappe/database/mariadb/database.py", line 106, in get_connection
    conn = self._get_connection()
           ^^^^^^^^^^^^^^^^^^^^^^
  File "/Users/shahin/frappe-demo/apps/frappe/frappe/database/mariadb/database.py", line 112, in _get_connection
    return self.create_connection()
           ^^^^^^^^^^^^^^^^^^^^^^^^
  File "/Users/shahin/frappe-demo/apps/frappe/frappe/database/mariadb/database.py", line 115, in create_connection
    return pymysql.connect(**self.get_connection_settings())
           ^^^^^^^^^^^^^^^^^^^^^^^^^^^^^^^^^^^^^^^^^^^^^^^^^
  File "/Users/shahin/frappe-demo/env/lib/python3.11/site-packages/pymysql/connections.py", line 361, in __init__
    self.connect()
  File "/Users/shahin/frappe-demo/env/lib/python3.11/site-packages/pymysql/connections.py", line 716, in connect
    raise exc
pymysql.err.OperationalError: (2003, "Can't connect to MySQL server on '127.0.0.1' ([Errno 61] Connection refused)")
2025-05-16 14:46:00,697 ERROR scheduler Exception in Enqueue Events for Site library.localhost
Traceback (most recent call last):
  File "/Users/shahin/frappe-demo/env/lib/python3.11/site-packages/pymysql/connections.py", line 649, in connect
    sock = socket.create_connection(
           ^^^^^^^^^^^^^^^^^^^^^^^^^
  File "/opt/homebrew/Cellar/python@3.11/3.11.12/Frameworks/Python.framework/Versions/3.11/lib/python3.11/socket.py", line 863, in create_connection
    raise exceptions[0]
  File "/opt/homebrew/Cellar/python@3.11/3.11.12/Frameworks/Python.framework/Versions/3.11/lib/python3.11/socket.py", line 848, in create_connection
    sock.connect(sa)
ConnectionRefusedError: [Errno 61] Connection refused

During handling of the above exception, another exception occurred:

Traceback (most recent call last):
  File "/Users/shahin/frappe-demo/apps/frappe/frappe/utils/scheduler.py", line 117, in enqueue_events_for_site
    if is_scheduler_inactive():
       ^^^^^^^^^^^^^^^^^^^^^^^
  File "/Users/shahin/frappe-demo/apps/frappe/frappe/utils/scheduler.py", line 161, in is_scheduler_inactive
    if is_scheduler_disabled(verbose=verbose):
       ^^^^^^^^^^^^^^^^^^^^^^^^^^^^^^^^^^^^^^
  File "/Users/shahin/frappe-demo/apps/frappe/frappe/utils/scheduler.py", line 174, in is_scheduler_disabled
    frappe.db.get_single_value("System Settings", "enable_scheduler")
  File "/Users/shahin/frappe-demo/apps/frappe/frappe/database/database.py", line 884, in get_single_value
    ).run()
      ^^^^^
  File "/Users/shahin/frappe-demo/apps/frappe/frappe/query_builder/utils.py", line 85, in execute_query
    result = frappe.db.sql(query, params, *args, **kwargs)  # nosemgrep
             ^^^^^^^^^^^^^^^^^^^^^^^^^^^^^^^^^^^^^^^^^^^^^
  File "/Users/shahin/frappe-demo/apps/frappe/frappe/database/database.py", line 237, in sql
    self.connect()
  File "/Users/shahin/frappe-demo/apps/frappe/frappe/database/database.py", line 135, in connect
    self.get_connection()
  File "/Users/shahin/frappe-demo/apps/frappe/frappe/database/mariadb/database.py", line 106, in get_connection
    conn = self._get_connection()
           ^^^^^^^^^^^^^^^^^^^^^^
  File "/Users/shahin/frappe-demo/apps/frappe/frappe/database/mariadb/database.py", line 112, in _get_connection
    return self.create_connection()
           ^^^^^^^^^^^^^^^^^^^^^^^^
  File "/Users/shahin/frappe-demo/apps/frappe/frappe/database/mariadb/database.py", line 115, in create_connection
    return pymysql.connect(**self.get_connection_settings())
           ^^^^^^^^^^^^^^^^^^^^^^^^^^^^^^^^^^^^^^^^^^^^^^^^^
  File "/Users/shahin/frappe-demo/env/lib/python3.11/site-packages/pymysql/connections.py", line 361, in __init__
    self.connect()
  File "/Users/shahin/frappe-demo/env/lib/python3.11/site-packages/pymysql/connections.py", line 716, in connect
    raise exc
pymysql.err.OperationalError: (2003, "Can't connect to MySQL server on '127.0.0.1' ([Errno 61] Connection refused)")
2025-05-16 14:50:00,712 ERROR scheduler Exception in Enqueue Events for Site library.localhost
Traceback (most recent call last):
  File "/Users/shahin/frappe-demo/env/lib/python3.11/site-packages/pymysql/connections.py", line 649, in connect
    sock = socket.create_connection(
           ^^^^^^^^^^^^^^^^^^^^^^^^^
  File "/opt/homebrew/Cellar/python@3.11/3.11.12/Frameworks/Python.framework/Versions/3.11/lib/python3.11/socket.py", line 863, in create_connection
    raise exceptions[0]
  File "/opt/homebrew/Cellar/python@3.11/3.11.12/Frameworks/Python.framework/Versions/3.11/lib/python3.11/socket.py", line 848, in create_connection
    sock.connect(sa)
ConnectionRefusedError: [Errno 61] Connection refused

During handling of the above exception, another exception occurred:

Traceback (most recent call last):
  File "/Users/shahin/frappe-demo/apps/frappe/frappe/utils/scheduler.py", line 117, in enqueue_events_for_site
    if is_scheduler_inactive():
       ^^^^^^^^^^^^^^^^^^^^^^^
  File "/Users/shahin/frappe-demo/apps/frappe/frappe/utils/scheduler.py", line 161, in is_scheduler_inactive
    if is_scheduler_disabled(verbose=verbose):
       ^^^^^^^^^^^^^^^^^^^^^^^^^^^^^^^^^^^^^^
  File "/Users/shahin/frappe-demo/apps/frappe/frappe/utils/scheduler.py", line 174, in is_scheduler_disabled
    frappe.db.get_single_value("System Settings", "enable_scheduler")
  File "/Users/shahin/frappe-demo/apps/frappe/frappe/database/database.py", line 884, in get_single_value
    ).run()
      ^^^^^
  File "/Users/shahin/frappe-demo/apps/frappe/frappe/query_builder/utils.py", line 85, in execute_query
    result = frappe.db.sql(query, params, *args, **kwargs)  # nosemgrep
             ^^^^^^^^^^^^^^^^^^^^^^^^^^^^^^^^^^^^^^^^^^^^^
  File "/Users/shahin/frappe-demo/apps/frappe/frappe/database/database.py", line 237, in sql
    self.connect()
  File "/Users/shahin/frappe-demo/apps/frappe/frappe/database/database.py", line 135, in connect
    self.get_connection()
  File "/Users/shahin/frappe-demo/apps/frappe/frappe/database/mariadb/database.py", line 106, in get_connection
    conn = self._get_connection()
           ^^^^^^^^^^^^^^^^^^^^^^
  File "/Users/shahin/frappe-demo/apps/frappe/frappe/database/mariadb/database.py", line 112, in _get_connection
    return self.create_connection()
           ^^^^^^^^^^^^^^^^^^^^^^^^
  File "/Users/shahin/frappe-demo/apps/frappe/frappe/database/mariadb/database.py", line 115, in create_connection
    return pymysql.connect(**self.get_connection_settings())
           ^^^^^^^^^^^^^^^^^^^^^^^^^^^^^^^^^^^^^^^^^^^^^^^^^
  File "/Users/shahin/frappe-demo/env/lib/python3.11/site-packages/pymysql/connections.py", line 361, in __init__
    self.connect()
  File "/Users/shahin/frappe-demo/env/lib/python3.11/site-packages/pymysql/connections.py", line 716, in connect
    raise exc
pymysql.err.OperationalError: (2003, "Can't connect to MySQL server on '127.0.0.1' ([Errno 61] Connection refused)")
2025-05-16 14:54:00,741 ERROR scheduler Exception in Enqueue Events for Site library.localhost
Traceback (most recent call last):
  File "/Users/shahin/frappe-demo/env/lib/python3.11/site-packages/pymysql/connections.py", line 649, in connect
    sock = socket.create_connection(
           ^^^^^^^^^^^^^^^^^^^^^^^^^
  File "/opt/homebrew/Cellar/python@3.11/3.11.12/Frameworks/Python.framework/Versions/3.11/lib/python3.11/socket.py", line 863, in create_connection
    raise exceptions[0]
  File "/opt/homebrew/Cellar/python@3.11/3.11.12/Frameworks/Python.framework/Versions/3.11/lib/python3.11/socket.py", line 848, in create_connection
    sock.connect(sa)
ConnectionRefusedError: [Errno 61] Connection refused

During handling of the above exception, another exception occurred:

Traceback (most recent call last):
  File "/Users/shahin/frappe-demo/apps/frappe/frappe/utils/scheduler.py", line 117, in enqueue_events_for_site
    if is_scheduler_inactive():
       ^^^^^^^^^^^^^^^^^^^^^^^
  File "/Users/shahin/frappe-demo/apps/frappe/frappe/utils/scheduler.py", line 161, in is_scheduler_inactive
    if is_scheduler_disabled(verbose=verbose):
       ^^^^^^^^^^^^^^^^^^^^^^^^^^^^^^^^^^^^^^
  File "/Users/shahin/frappe-demo/apps/frappe/frappe/utils/scheduler.py", line 174, in is_scheduler_disabled
    frappe.db.get_single_value("System Settings", "enable_scheduler")
  File "/Users/shahin/frappe-demo/apps/frappe/frappe/database/database.py", line 884, in get_single_value
    ).run()
      ^^^^^
  File "/Users/shahin/frappe-demo/apps/frappe/frappe/query_builder/utils.py", line 85, in execute_query
    result = frappe.db.sql(query, params, *args, **kwargs)  # nosemgrep
             ^^^^^^^^^^^^^^^^^^^^^^^^^^^^^^^^^^^^^^^^^^^^^
  File "/Users/shahin/frappe-demo/apps/frappe/frappe/database/database.py", line 237, in sql
    self.connect()
  File "/Users/shahin/frappe-demo/apps/frappe/frappe/database/database.py", line 135, in connect
    self.get_connection()
  File "/Users/shahin/frappe-demo/apps/frappe/frappe/database/mariadb/database.py", line 106, in get_connection
    conn = self._get_connection()
           ^^^^^^^^^^^^^^^^^^^^^^
  File "/Users/shahin/frappe-demo/apps/frappe/frappe/database/mariadb/database.py", line 112, in _get_connection
    return self.create_connection()
           ^^^^^^^^^^^^^^^^^^^^^^^^
  File "/Users/shahin/frappe-demo/apps/frappe/frappe/database/mariadb/database.py", line 115, in create_connection
    return pymysql.connect(**self.get_connection_settings())
           ^^^^^^^^^^^^^^^^^^^^^^^^^^^^^^^^^^^^^^^^^^^^^^^^^
  File "/Users/shahin/frappe-demo/env/lib/python3.11/site-packages/pymysql/connections.py", line 361, in __init__
    self.connect()
  File "/Users/shahin/frappe-demo/env/lib/python3.11/site-packages/pymysql/connections.py", line 716, in connect
    raise exc
pymysql.err.OperationalError: (2003, "Can't connect to MySQL server on '127.0.0.1' ([Errno 61] Connection refused)")
2025-05-16 14:58:00,759 ERROR scheduler Exception in Enqueue Events for Site library.localhost
Traceback (most recent call last):
  File "/Users/shahin/frappe-demo/env/lib/python3.11/site-packages/pymysql/connections.py", line 649, in connect
    sock = socket.create_connection(
           ^^^^^^^^^^^^^^^^^^^^^^^^^
  File "/opt/homebrew/Cellar/python@3.11/3.11.12/Frameworks/Python.framework/Versions/3.11/lib/python3.11/socket.py", line 863, in create_connection
    raise exceptions[0]
  File "/opt/homebrew/Cellar/python@3.11/3.11.12/Frameworks/Python.framework/Versions/3.11/lib/python3.11/socket.py", line 848, in create_connection
    sock.connect(sa)
ConnectionRefusedError: [Errno 61] Connection refused

During handling of the above exception, another exception occurred:

Traceback (most recent call last):
  File "/Users/shahin/frappe-demo/apps/frappe/frappe/utils/scheduler.py", line 117, in enqueue_events_for_site
    if is_scheduler_inactive():
       ^^^^^^^^^^^^^^^^^^^^^^^
  File "/Users/shahin/frappe-demo/apps/frappe/frappe/utils/scheduler.py", line 161, in is_scheduler_inactive
    if is_scheduler_disabled(verbose=verbose):
       ^^^^^^^^^^^^^^^^^^^^^^^^^^^^^^^^^^^^^^
  File "/Users/shahin/frappe-demo/apps/frappe/frappe/utils/scheduler.py", line 174, in is_scheduler_disabled
    frappe.db.get_single_value("System Settings", "enable_scheduler")
  File "/Users/shahin/frappe-demo/apps/frappe/frappe/database/database.py", line 884, in get_single_value
    ).run()
      ^^^^^
  File "/Users/shahin/frappe-demo/apps/frappe/frappe/query_builder/utils.py", line 85, in execute_query
    result = frappe.db.sql(query, params, *args, **kwargs)  # nosemgrep
             ^^^^^^^^^^^^^^^^^^^^^^^^^^^^^^^^^^^^^^^^^^^^^
  File "/Users/shahin/frappe-demo/apps/frappe/frappe/database/database.py", line 237, in sql
    self.connect()
  File "/Users/shahin/frappe-demo/apps/frappe/frappe/database/database.py", line 135, in connect
    self.get_connection()
  File "/Users/shahin/frappe-demo/apps/frappe/frappe/database/mariadb/database.py", line 106, in get_connection
    conn = self._get_connection()
           ^^^^^^^^^^^^^^^^^^^^^^
  File "/Users/shahin/frappe-demo/apps/frappe/frappe/database/mariadb/database.py", line 112, in _get_connection
    return self.create_connection()
           ^^^^^^^^^^^^^^^^^^^^^^^^
  File "/Users/shahin/frappe-demo/apps/frappe/frappe/database/mariadb/database.py", line 115, in create_connection
    return pymysql.connect(**self.get_connection_settings())
           ^^^^^^^^^^^^^^^^^^^^^^^^^^^^^^^^^^^^^^^^^^^^^^^^^
  File "/Users/shahin/frappe-demo/env/lib/python3.11/site-packages/pymysql/connections.py", line 361, in __init__
    self.connect()
  File "/Users/shahin/frappe-demo/env/lib/python3.11/site-packages/pymysql/connections.py", line 716, in connect
    raise exc
pymysql.err.OperationalError: (2003, "Can't connect to MySQL server on '127.0.0.1' ([Errno 61] Connection refused)")
2025-05-16 15:02:00,785 ERROR scheduler Exception in Enqueue Events for Site library.localhost
Traceback (most recent call last):
  File "/Users/shahin/frappe-demo/env/lib/python3.11/site-packages/pymysql/connections.py", line 649, in connect
    sock = socket.create_connection(
           ^^^^^^^^^^^^^^^^^^^^^^^^^
  File "/opt/homebrew/Cellar/python@3.11/3.11.12/Frameworks/Python.framework/Versions/3.11/lib/python3.11/socket.py", line 863, in create_connection
    raise exceptions[0]
  File "/opt/homebrew/Cellar/python@3.11/3.11.12/Frameworks/Python.framework/Versions/3.11/lib/python3.11/socket.py", line 848, in create_connection
    sock.connect(sa)
ConnectionRefusedError: [Errno 61] Connection refused

During handling of the above exception, another exception occurred:

Traceback (most recent call last):
  File "/Users/shahin/frappe-demo/apps/frappe/frappe/utils/scheduler.py", line 117, in enqueue_events_for_site
    if is_scheduler_inactive():
       ^^^^^^^^^^^^^^^^^^^^^^^
  File "/Users/shahin/frappe-demo/apps/frappe/frappe/utils/scheduler.py", line 161, in is_scheduler_inactive
    if is_scheduler_disabled(verbose=verbose):
       ^^^^^^^^^^^^^^^^^^^^^^^^^^^^^^^^^^^^^^
  File "/Users/shahin/frappe-demo/apps/frappe/frappe/utils/scheduler.py", line 174, in is_scheduler_disabled
    frappe.db.get_single_value("System Settings", "enable_scheduler")
  File "/Users/shahin/frappe-demo/apps/frappe/frappe/database/database.py", line 884, in get_single_value
    ).run()
      ^^^^^
  File "/Users/shahin/frappe-demo/apps/frappe/frappe/query_builder/utils.py", line 85, in execute_query
    result = frappe.db.sql(query, params, *args, **kwargs)  # nosemgrep
             ^^^^^^^^^^^^^^^^^^^^^^^^^^^^^^^^^^^^^^^^^^^^^
  File "/Users/shahin/frappe-demo/apps/frappe/frappe/database/database.py", line 237, in sql
    self.connect()
  File "/Users/shahin/frappe-demo/apps/frappe/frappe/database/database.py", line 135, in connect
    self.get_connection()
  File "/Users/shahin/frappe-demo/apps/frappe/frappe/database/mariadb/database.py", line 106, in get_connection
    conn = self._get_connection()
           ^^^^^^^^^^^^^^^^^^^^^^
  File "/Users/shahin/frappe-demo/apps/frappe/frappe/database/mariadb/database.py", line 112, in _get_connection
    return self.create_connection()
           ^^^^^^^^^^^^^^^^^^^^^^^^
  File "/Users/shahin/frappe-demo/apps/frappe/frappe/database/mariadb/database.py", line 115, in create_connection
    return pymysql.connect(**self.get_connection_settings())
           ^^^^^^^^^^^^^^^^^^^^^^^^^^^^^^^^^^^^^^^^^^^^^^^^^
  File "/Users/shahin/frappe-demo/env/lib/python3.11/site-packages/pymysql/connections.py", line 361, in __init__
    self.connect()
  File "/Users/shahin/frappe-demo/env/lib/python3.11/site-packages/pymysql/connections.py", line 716, in connect
    raise exc
pymysql.err.OperationalError: (2003, "Can't connect to MySQL server on '127.0.0.1' ([Errno 61] Connection refused)")
2025-05-16 15:06:00,806 ERROR scheduler Exception in Enqueue Events for Site library.localhost
Traceback (most recent call last):
  File "/Users/shahin/frappe-demo/env/lib/python3.11/site-packages/pymysql/connections.py", line 649, in connect
    sock = socket.create_connection(
           ^^^^^^^^^^^^^^^^^^^^^^^^^
  File "/opt/homebrew/Cellar/python@3.11/3.11.12/Frameworks/Python.framework/Versions/3.11/lib/python3.11/socket.py", line 863, in create_connection
    raise exceptions[0]
  File "/opt/homebrew/Cellar/python@3.11/3.11.12/Frameworks/Python.framework/Versions/3.11/lib/python3.11/socket.py", line 848, in create_connection
    sock.connect(sa)
ConnectionRefusedError: [Errno 61] Connection refused

During handling of the above exception, another exception occurred:

Traceback (most recent call last):
  File "/Users/shahin/frappe-demo/apps/frappe/frappe/utils/scheduler.py", line 117, in enqueue_events_for_site
    if is_scheduler_inactive():
       ^^^^^^^^^^^^^^^^^^^^^^^
  File "/Users/shahin/frappe-demo/apps/frappe/frappe/utils/scheduler.py", line 161, in is_scheduler_inactive
    if is_scheduler_disabled(verbose=verbose):
       ^^^^^^^^^^^^^^^^^^^^^^^^^^^^^^^^^^^^^^
  File "/Users/shahin/frappe-demo/apps/frappe/frappe/utils/scheduler.py", line 174, in is_scheduler_disabled
    frappe.db.get_single_value("System Settings", "enable_scheduler")
  File "/Users/shahin/frappe-demo/apps/frappe/frappe/database/database.py", line 884, in get_single_value
    ).run()
      ^^^^^
  File "/Users/shahin/frappe-demo/apps/frappe/frappe/query_builder/utils.py", line 85, in execute_query
    result = frappe.db.sql(query, params, *args, **kwargs)  # nosemgrep
             ^^^^^^^^^^^^^^^^^^^^^^^^^^^^^^^^^^^^^^^^^^^^^
  File "/Users/shahin/frappe-demo/apps/frappe/frappe/database/database.py", line 237, in sql
    self.connect()
  File "/Users/shahin/frappe-demo/apps/frappe/frappe/database/database.py", line 135, in connect
    self.get_connection()
  File "/Users/shahin/frappe-demo/apps/frappe/frappe/database/mariadb/database.py", line 106, in get_connection
    conn = self._get_connection()
           ^^^^^^^^^^^^^^^^^^^^^^
  File "/Users/shahin/frappe-demo/apps/frappe/frappe/database/mariadb/database.py", line 112, in _get_connection
    return self.create_connection()
           ^^^^^^^^^^^^^^^^^^^^^^^^
  File "/Users/shahin/frappe-demo/apps/frappe/frappe/database/mariadb/database.py", line 115, in create_connection
    return pymysql.connect(**self.get_connection_settings())
           ^^^^^^^^^^^^^^^^^^^^^^^^^^^^^^^^^^^^^^^^^^^^^^^^^
  File "/Users/shahin/frappe-demo/env/lib/python3.11/site-packages/pymysql/connections.py", line 361, in __init__
    self.connect()
  File "/Users/shahin/frappe-demo/env/lib/python3.11/site-packages/pymysql/connections.py", line 716, in connect
    raise exc
pymysql.err.OperationalError: (2003, "Can't connect to MySQL server on '127.0.0.1' ([Errno 61] Connection refused)")
2025-05-16 15:10:00,758 ERROR scheduler Exception in Enqueue Events for Site library.localhost
Traceback (most recent call last):
  File "/Users/shahin/frappe-demo/env/lib/python3.11/site-packages/pymysql/connections.py", line 649, in connect
    sock = socket.create_connection(
           ^^^^^^^^^^^^^^^^^^^^^^^^^
  File "/opt/homebrew/Cellar/python@3.11/3.11.12/Frameworks/Python.framework/Versions/3.11/lib/python3.11/socket.py", line 863, in create_connection
    raise exceptions[0]
  File "/opt/homebrew/Cellar/python@3.11/3.11.12/Frameworks/Python.framework/Versions/3.11/lib/python3.11/socket.py", line 848, in create_connection
    sock.connect(sa)
ConnectionRefusedError: [Errno 61] Connection refused

During handling of the above exception, another exception occurred:

Traceback (most recent call last):
  File "/Users/shahin/frappe-demo/apps/frappe/frappe/utils/scheduler.py", line 117, in enqueue_events_for_site
    if is_scheduler_inactive():
       ^^^^^^^^^^^^^^^^^^^^^^^
  File "/Users/shahin/frappe-demo/apps/frappe/frappe/utils/scheduler.py", line 161, in is_scheduler_inactive
    if is_scheduler_disabled(verbose=verbose):
       ^^^^^^^^^^^^^^^^^^^^^^^^^^^^^^^^^^^^^^
  File "/Users/shahin/frappe-demo/apps/frappe/frappe/utils/scheduler.py", line 174, in is_scheduler_disabled
    frappe.db.get_single_value("System Settings", "enable_scheduler")
  File "/Users/shahin/frappe-demo/apps/frappe/frappe/database/database.py", line 884, in get_single_value
    ).run()
      ^^^^^
  File "/Users/shahin/frappe-demo/apps/frappe/frappe/query_builder/utils.py", line 85, in execute_query
    result = frappe.db.sql(query, params, *args, **kwargs)  # nosemgrep
             ^^^^^^^^^^^^^^^^^^^^^^^^^^^^^^^^^^^^^^^^^^^^^
  File "/Users/shahin/frappe-demo/apps/frappe/frappe/database/database.py", line 237, in sql
    self.connect()
  File "/Users/shahin/frappe-demo/apps/frappe/frappe/database/database.py", line 135, in connect
    self.get_connection()
  File "/Users/shahin/frappe-demo/apps/frappe/frappe/database/mariadb/database.py", line 106, in get_connection
    conn = self._get_connection()
           ^^^^^^^^^^^^^^^^^^^^^^
  File "/Users/shahin/frappe-demo/apps/frappe/frappe/database/mariadb/database.py", line 112, in _get_connection
    return self.create_connection()
           ^^^^^^^^^^^^^^^^^^^^^^^^
  File "/Users/shahin/frappe-demo/apps/frappe/frappe/database/mariadb/database.py", line 115, in create_connection
    return pymysql.connect(**self.get_connection_settings())
           ^^^^^^^^^^^^^^^^^^^^^^^^^^^^^^^^^^^^^^^^^^^^^^^^^
  File "/Users/shahin/frappe-demo/env/lib/python3.11/site-packages/pymysql/connections.py", line 361, in __init__
    self.connect()
  File "/Users/shahin/frappe-demo/env/lib/python3.11/site-packages/pymysql/connections.py", line 716, in connect
    raise exc
pymysql.err.OperationalError: (2003, "Can't connect to MySQL server on '127.0.0.1' ([Errno 61] Connection refused)")
2025-05-16 15:14:00,769 ERROR scheduler Exception in Enqueue Events for Site library.localhost
Traceback (most recent call last):
  File "/Users/shahin/frappe-demo/env/lib/python3.11/site-packages/pymysql/connections.py", line 649, in connect
    sock = socket.create_connection(
           ^^^^^^^^^^^^^^^^^^^^^^^^^
  File "/opt/homebrew/Cellar/python@3.11/3.11.12/Frameworks/Python.framework/Versions/3.11/lib/python3.11/socket.py", line 863, in create_connection
    raise exceptions[0]
  File "/opt/homebrew/Cellar/python@3.11/3.11.12/Frameworks/Python.framework/Versions/3.11/lib/python3.11/socket.py", line 848, in create_connection
    sock.connect(sa)
ConnectionRefusedError: [Errno 61] Connection refused

During handling of the above exception, another exception occurred:

Traceback (most recent call last):
  File "/Users/shahin/frappe-demo/apps/frappe/frappe/utils/scheduler.py", line 117, in enqueue_events_for_site
    if is_scheduler_inactive():
       ^^^^^^^^^^^^^^^^^^^^^^^
  File "/Users/shahin/frappe-demo/apps/frappe/frappe/utils/scheduler.py", line 161, in is_scheduler_inactive
    if is_scheduler_disabled(verbose=verbose):
       ^^^^^^^^^^^^^^^^^^^^^^^^^^^^^^^^^^^^^^
  File "/Users/shahin/frappe-demo/apps/frappe/frappe/utils/scheduler.py", line 174, in is_scheduler_disabled
    frappe.db.get_single_value("System Settings", "enable_scheduler")
  File "/Users/shahin/frappe-demo/apps/frappe/frappe/database/database.py", line 884, in get_single_value
    ).run()
      ^^^^^
  File "/Users/shahin/frappe-demo/apps/frappe/frappe/query_builder/utils.py", line 85, in execute_query
    result = frappe.db.sql(query, params, *args, **kwargs)  # nosemgrep
             ^^^^^^^^^^^^^^^^^^^^^^^^^^^^^^^^^^^^^^^^^^^^^
  File "/Users/shahin/frappe-demo/apps/frappe/frappe/database/database.py", line 237, in sql
    self.connect()
  File "/Users/shahin/frappe-demo/apps/frappe/frappe/database/database.py", line 135, in connect
    self.get_connection()
  File "/Users/shahin/frappe-demo/apps/frappe/frappe/database/mariadb/database.py", line 106, in get_connection
    conn = self._get_connection()
           ^^^^^^^^^^^^^^^^^^^^^^
  File "/Users/shahin/frappe-demo/apps/frappe/frappe/database/mariadb/database.py", line 112, in _get_connection
    return self.create_connection()
           ^^^^^^^^^^^^^^^^^^^^^^^^
  File "/Users/shahin/frappe-demo/apps/frappe/frappe/database/mariadb/database.py", line 115, in create_connection
    return pymysql.connect(**self.get_connection_settings())
           ^^^^^^^^^^^^^^^^^^^^^^^^^^^^^^^^^^^^^^^^^^^^^^^^^
  File "/Users/shahin/frappe-demo/env/lib/python3.11/site-packages/pymysql/connections.py", line 361, in __init__
    self.connect()
  File "/Users/shahin/frappe-demo/env/lib/python3.11/site-packages/pymysql/connections.py", line 716, in connect
    raise exc
pymysql.err.OperationalError: (2003, "Can't connect to MySQL server on '127.0.0.1' ([Errno 61] Connection refused)")
2025-05-16 15:41:16,498 ERROR scheduler Exception in Enqueue Events for Site library.localhost
Traceback (most recent call last):
  File "/Users/shahin/frappe-demo/env/lib/python3.11/site-packages/pymysql/connections.py", line 649, in connect
    sock = socket.create_connection(
           ^^^^^^^^^^^^^^^^^^^^^^^^^
  File "/opt/homebrew/Cellar/python@3.11/3.11.12/Frameworks/Python.framework/Versions/3.11/lib/python3.11/socket.py", line 863, in create_connection
    raise exceptions[0]
  File "/opt/homebrew/Cellar/python@3.11/3.11.12/Frameworks/Python.framework/Versions/3.11/lib/python3.11/socket.py", line 848, in create_connection
    sock.connect(sa)
ConnectionRefusedError: [Errno 61] Connection refused

During handling of the above exception, another exception occurred:

Traceback (most recent call last):
  File "/Users/shahin/frappe-demo/apps/frappe/frappe/utils/scheduler.py", line 117, in enqueue_events_for_site
    if is_scheduler_inactive():
       ^^^^^^^^^^^^^^^^^^^^^^^
  File "/Users/shahin/frappe-demo/apps/frappe/frappe/utils/scheduler.py", line 161, in is_scheduler_inactive
    if is_scheduler_disabled(verbose=verbose):
       ^^^^^^^^^^^^^^^^^^^^^^^^^^^^^^^^^^^^^^
  File "/Users/shahin/frappe-demo/apps/frappe/frappe/utils/scheduler.py", line 174, in is_scheduler_disabled
    frappe.db.get_single_value("System Settings", "enable_scheduler")
  File "/Users/shahin/frappe-demo/apps/frappe/frappe/database/database.py", line 884, in get_single_value
    ).run()
      ^^^^^
  File "/Users/shahin/frappe-demo/apps/frappe/frappe/query_builder/utils.py", line 85, in execute_query
    result = frappe.db.sql(query, params, *args, **kwargs)  # nosemgrep
             ^^^^^^^^^^^^^^^^^^^^^^^^^^^^^^^^^^^^^^^^^^^^^
  File "/Users/shahin/frappe-demo/apps/frappe/frappe/database/database.py", line 237, in sql
    self.connect()
  File "/Users/shahin/frappe-demo/apps/frappe/frappe/database/database.py", line 135, in connect
    self.get_connection()
  File "/Users/shahin/frappe-demo/apps/frappe/frappe/database/mariadb/database.py", line 106, in get_connection
    conn = self._get_connection()
           ^^^^^^^^^^^^^^^^^^^^^^
  File "/Users/shahin/frappe-demo/apps/frappe/frappe/database/mariadb/database.py", line 112, in _get_connection
    return self.create_connection()
           ^^^^^^^^^^^^^^^^^^^^^^^^
  File "/Users/shahin/frappe-demo/apps/frappe/frappe/database/mariadb/database.py", line 115, in create_connection
    return pymysql.connect(**self.get_connection_settings())
           ^^^^^^^^^^^^^^^^^^^^^^^^^^^^^^^^^^^^^^^^^^^^^^^^^
  File "/Users/shahin/frappe-demo/env/lib/python3.11/site-packages/pymysql/connections.py", line 361, in __init__
    self.connect()
  File "/Users/shahin/frappe-demo/env/lib/python3.11/site-packages/pymysql/connections.py", line 716, in connect
    raise exc
pymysql.err.OperationalError: (2003, "Can't connect to MySQL server on '127.0.0.1' ([Errno 61] Connection refused)")
2025-05-16 15:42:00,524 ERROR scheduler Exception in Enqueue Events for Site library.localhost
Traceback (most recent call last):
  File "/Users/shahin/frappe-demo/env/lib/python3.11/site-packages/pymysql/connections.py", line 649, in connect
    sock = socket.create_connection(
           ^^^^^^^^^^^^^^^^^^^^^^^^^
  File "/opt/homebrew/Cellar/python@3.11/3.11.12/Frameworks/Python.framework/Versions/3.11/lib/python3.11/socket.py", line 863, in create_connection
    raise exceptions[0]
  File "/opt/homebrew/Cellar/python@3.11/3.11.12/Frameworks/Python.framework/Versions/3.11/lib/python3.11/socket.py", line 848, in create_connection
    sock.connect(sa)
ConnectionRefusedError: [Errno 61] Connection refused

During handling of the above exception, another exception occurred:

Traceback (most recent call last):
  File "/Users/shahin/frappe-demo/apps/frappe/frappe/utils/scheduler.py", line 117, in enqueue_events_for_site
    if is_scheduler_inactive():
       ^^^^^^^^^^^^^^^^^^^^^^^
  File "/Users/shahin/frappe-demo/apps/frappe/frappe/utils/scheduler.py", line 161, in is_scheduler_inactive
    if is_scheduler_disabled(verbose=verbose):
       ^^^^^^^^^^^^^^^^^^^^^^^^^^^^^^^^^^^^^^
  File "/Users/shahin/frappe-demo/apps/frappe/frappe/utils/scheduler.py", line 174, in is_scheduler_disabled
    frappe.db.get_single_value("System Settings", "enable_scheduler")
  File "/Users/shahin/frappe-demo/apps/frappe/frappe/database/database.py", line 884, in get_single_value
    ).run()
      ^^^^^
  File "/Users/shahin/frappe-demo/apps/frappe/frappe/query_builder/utils.py", line 85, in execute_query
    result = frappe.db.sql(query, params, *args, **kwargs)  # nosemgrep
             ^^^^^^^^^^^^^^^^^^^^^^^^^^^^^^^^^^^^^^^^^^^^^
  File "/Users/shahin/frappe-demo/apps/frappe/frappe/database/database.py", line 237, in sql
    self.connect()
  File "/Users/shahin/frappe-demo/apps/frappe/frappe/database/database.py", line 135, in connect
    self.get_connection()
  File "/Users/shahin/frappe-demo/apps/frappe/frappe/database/mariadb/database.py", line 106, in get_connection
    conn = self._get_connection()
           ^^^^^^^^^^^^^^^^^^^^^^
  File "/Users/shahin/frappe-demo/apps/frappe/frappe/database/mariadb/database.py", line 112, in _get_connection
    return self.create_connection()
           ^^^^^^^^^^^^^^^^^^^^^^^^
  File "/Users/shahin/frappe-demo/apps/frappe/frappe/database/mariadb/database.py", line 115, in create_connection
    return pymysql.connect(**self.get_connection_settings())
           ^^^^^^^^^^^^^^^^^^^^^^^^^^^^^^^^^^^^^^^^^^^^^^^^^
  File "/Users/shahin/frappe-demo/env/lib/python3.11/site-packages/pymysql/connections.py", line 361, in __init__
    self.connect()
  File "/Users/shahin/frappe-demo/env/lib/python3.11/site-packages/pymysql/connections.py", line 716, in connect
    raise exc
pymysql.err.OperationalError: (2003, "Can't connect to MySQL server on '127.0.0.1' ([Errno 61] Connection refused)")
2025-05-16 15:46:00,551 ERROR scheduler Exception in Enqueue Events for Site library.localhost
Traceback (most recent call last):
  File "/Users/shahin/frappe-demo/env/lib/python3.11/site-packages/pymysql/connections.py", line 649, in connect
    sock = socket.create_connection(
           ^^^^^^^^^^^^^^^^^^^^^^^^^
  File "/opt/homebrew/Cellar/python@3.11/3.11.12/Frameworks/Python.framework/Versions/3.11/lib/python3.11/socket.py", line 863, in create_connection
    raise exceptions[0]
  File "/opt/homebrew/Cellar/python@3.11/3.11.12/Frameworks/Python.framework/Versions/3.11/lib/python3.11/socket.py", line 848, in create_connection
    sock.connect(sa)
ConnectionRefusedError: [Errno 61] Connection refused

During handling of the above exception, another exception occurred:

Traceback (most recent call last):
  File "/Users/shahin/frappe-demo/apps/frappe/frappe/utils/scheduler.py", line 117, in enqueue_events_for_site
    if is_scheduler_inactive():
       ^^^^^^^^^^^^^^^^^^^^^^^
  File "/Users/shahin/frappe-demo/apps/frappe/frappe/utils/scheduler.py", line 161, in is_scheduler_inactive
    if is_scheduler_disabled(verbose=verbose):
       ^^^^^^^^^^^^^^^^^^^^^^^^^^^^^^^^^^^^^^
  File "/Users/shahin/frappe-demo/apps/frappe/frappe/utils/scheduler.py", line 174, in is_scheduler_disabled
    frappe.db.get_single_value("System Settings", "enable_scheduler")
  File "/Users/shahin/frappe-demo/apps/frappe/frappe/database/database.py", line 884, in get_single_value
    ).run()
      ^^^^^
  File "/Users/shahin/frappe-demo/apps/frappe/frappe/query_builder/utils.py", line 85, in execute_query
    result = frappe.db.sql(query, params, *args, **kwargs)  # nosemgrep
             ^^^^^^^^^^^^^^^^^^^^^^^^^^^^^^^^^^^^^^^^^^^^^
  File "/Users/shahin/frappe-demo/apps/frappe/frappe/database/database.py", line 237, in sql
    self.connect()
  File "/Users/shahin/frappe-demo/apps/frappe/frappe/database/database.py", line 135, in connect
    self.get_connection()
  File "/Users/shahin/frappe-demo/apps/frappe/frappe/database/mariadb/database.py", line 106, in get_connection
    conn = self._get_connection()
           ^^^^^^^^^^^^^^^^^^^^^^
  File "/Users/shahin/frappe-demo/apps/frappe/frappe/database/mariadb/database.py", line 112, in _get_connection
    return self.create_connection()
           ^^^^^^^^^^^^^^^^^^^^^^^^
  File "/Users/shahin/frappe-demo/apps/frappe/frappe/database/mariadb/database.py", line 115, in create_connection
    return pymysql.connect(**self.get_connection_settings())
           ^^^^^^^^^^^^^^^^^^^^^^^^^^^^^^^^^^^^^^^^^^^^^^^^^
  File "/Users/shahin/frappe-demo/env/lib/python3.11/site-packages/pymysql/connections.py", line 361, in __init__
    self.connect()
  File "/Users/shahin/frappe-demo/env/lib/python3.11/site-packages/pymysql/connections.py", line 716, in connect
    raise exc
pymysql.err.OperationalError: (2003, "Can't connect to MySQL server on '127.0.0.1' ([Errno 61] Connection refused)")
2025-05-16 15:50:00,593 ERROR scheduler Exception in Enqueue Events for Site library.localhost
Traceback (most recent call last):
  File "/Users/shahin/frappe-demo/env/lib/python3.11/site-packages/pymysql/connections.py", line 649, in connect
    sock = socket.create_connection(
           ^^^^^^^^^^^^^^^^^^^^^^^^^
  File "/opt/homebrew/Cellar/python@3.11/3.11.12/Frameworks/Python.framework/Versions/3.11/lib/python3.11/socket.py", line 863, in create_connection
    raise exceptions[0]
  File "/opt/homebrew/Cellar/python@3.11/3.11.12/Frameworks/Python.framework/Versions/3.11/lib/python3.11/socket.py", line 848, in create_connection
    sock.connect(sa)
ConnectionRefusedError: [Errno 61] Connection refused

During handling of the above exception, another exception occurred:

Traceback (most recent call last):
  File "/Users/shahin/frappe-demo/apps/frappe/frappe/utils/scheduler.py", line 117, in enqueue_events_for_site
    if is_scheduler_inactive():
       ^^^^^^^^^^^^^^^^^^^^^^^
  File "/Users/shahin/frappe-demo/apps/frappe/frappe/utils/scheduler.py", line 161, in is_scheduler_inactive
    if is_scheduler_disabled(verbose=verbose):
       ^^^^^^^^^^^^^^^^^^^^^^^^^^^^^^^^^^^^^^
  File "/Users/shahin/frappe-demo/apps/frappe/frappe/utils/scheduler.py", line 174, in is_scheduler_disabled
    frappe.db.get_single_value("System Settings", "enable_scheduler")
  File "/Users/shahin/frappe-demo/apps/frappe/frappe/database/database.py", line 884, in get_single_value
    ).run()
      ^^^^^
  File "/Users/shahin/frappe-demo/apps/frappe/frappe/query_builder/utils.py", line 85, in execute_query
    result = frappe.db.sql(query, params, *args, **kwargs)  # nosemgrep
             ^^^^^^^^^^^^^^^^^^^^^^^^^^^^^^^^^^^^^^^^^^^^^
  File "/Users/shahin/frappe-demo/apps/frappe/frappe/database/database.py", line 237, in sql
    self.connect()
  File "/Users/shahin/frappe-demo/apps/frappe/frappe/database/database.py", line 135, in connect
    self.get_connection()
  File "/Users/shahin/frappe-demo/apps/frappe/frappe/database/mariadb/database.py", line 106, in get_connection
    conn = self._get_connection()
           ^^^^^^^^^^^^^^^^^^^^^^
  File "/Users/shahin/frappe-demo/apps/frappe/frappe/database/mariadb/database.py", line 112, in _get_connection
    return self.create_connection()
           ^^^^^^^^^^^^^^^^^^^^^^^^
  File "/Users/shahin/frappe-demo/apps/frappe/frappe/database/mariadb/database.py", line 115, in create_connection
    return pymysql.connect(**self.get_connection_settings())
           ^^^^^^^^^^^^^^^^^^^^^^^^^^^^^^^^^^^^^^^^^^^^^^^^^
  File "/Users/shahin/frappe-demo/env/lib/python3.11/site-packages/pymysql/connections.py", line 361, in __init__
    self.connect()
  File "/Users/shahin/frappe-demo/env/lib/python3.11/site-packages/pymysql/connections.py", line 716, in connect
    raise exc
pymysql.err.OperationalError: (2003, "Can't connect to MySQL server on '127.0.0.1' ([Errno 61] Connection refused)")
2025-05-16 15:54:00,608 ERROR scheduler Exception in Enqueue Events for Site library.localhost
Traceback (most recent call last):
  File "/Users/shahin/frappe-demo/env/lib/python3.11/site-packages/pymysql/connections.py", line 649, in connect
    sock = socket.create_connection(
           ^^^^^^^^^^^^^^^^^^^^^^^^^
  File "/opt/homebrew/Cellar/python@3.11/3.11.12/Frameworks/Python.framework/Versions/3.11/lib/python3.11/socket.py", line 863, in create_connection
    raise exceptions[0]
  File "/opt/homebrew/Cellar/python@3.11/3.11.12/Frameworks/Python.framework/Versions/3.11/lib/python3.11/socket.py", line 848, in create_connection
    sock.connect(sa)
ConnectionRefusedError: [Errno 61] Connection refused

During handling of the above exception, another exception occurred:

Traceback (most recent call last):
  File "/Users/shahin/frappe-demo/apps/frappe/frappe/utils/scheduler.py", line 117, in enqueue_events_for_site
    if is_scheduler_inactive():
       ^^^^^^^^^^^^^^^^^^^^^^^
  File "/Users/shahin/frappe-demo/apps/frappe/frappe/utils/scheduler.py", line 161, in is_scheduler_inactive
    if is_scheduler_disabled(verbose=verbose):
       ^^^^^^^^^^^^^^^^^^^^^^^^^^^^^^^^^^^^^^
  File "/Users/shahin/frappe-demo/apps/frappe/frappe/utils/scheduler.py", line 174, in is_scheduler_disabled
    frappe.db.get_single_value("System Settings", "enable_scheduler")
  File "/Users/shahin/frappe-demo/apps/frappe/frappe/database/database.py", line 884, in get_single_value
    ).run()
      ^^^^^
  File "/Users/shahin/frappe-demo/apps/frappe/frappe/query_builder/utils.py", line 85, in execute_query
    result = frappe.db.sql(query, params, *args, **kwargs)  # nosemgrep
             ^^^^^^^^^^^^^^^^^^^^^^^^^^^^^^^^^^^^^^^^^^^^^
  File "/Users/shahin/frappe-demo/apps/frappe/frappe/database/database.py", line 237, in sql
    self.connect()
  File "/Users/shahin/frappe-demo/apps/frappe/frappe/database/database.py", line 135, in connect
    self.get_connection()
  File "/Users/shahin/frappe-demo/apps/frappe/frappe/database/mariadb/database.py", line 106, in get_connection
    conn = self._get_connection()
           ^^^^^^^^^^^^^^^^^^^^^^
  File "/Users/shahin/frappe-demo/apps/frappe/frappe/database/mariadb/database.py", line 112, in _get_connection
    return self.create_connection()
           ^^^^^^^^^^^^^^^^^^^^^^^^
  File "/Users/shahin/frappe-demo/apps/frappe/frappe/database/mariadb/database.py", line 115, in create_connection
    return pymysql.connect(**self.get_connection_settings())
           ^^^^^^^^^^^^^^^^^^^^^^^^^^^^^^^^^^^^^^^^^^^^^^^^^
  File "/Users/shahin/frappe-demo/env/lib/python3.11/site-packages/pymysql/connections.py", line 361, in __init__
    self.connect()
  File "/Users/shahin/frappe-demo/env/lib/python3.11/site-packages/pymysql/connections.py", line 716, in connect
    raise exc
pymysql.err.OperationalError: (2003, "Can't connect to MySQL server on '127.0.0.1' ([Errno 61] Connection refused)")
2025-05-16 15:58:00,652 ERROR scheduler Exception in Enqueue Events for Site library.localhost
Traceback (most recent call last):
  File "/Users/shahin/frappe-demo/apps/frappe/frappe/utils/scheduler.py", line 117, in enqueue_events_for_site
    if is_scheduler_inactive():
       ^^^^^^^^^^^^^^^^^^^^^^^
  File "/Users/shahin/frappe-demo/apps/frappe/frappe/utils/scheduler.py", line 161, in is_scheduler_inactive
    if is_scheduler_disabled(verbose=verbose):
       ^^^^^^^^^^^^^^^^^^^^^^^^^^^^^^^^^^^^^^
  File "/Users/shahin/frappe-demo/apps/frappe/frappe/utils/scheduler.py", line 174, in is_scheduler_disabled
    frappe.db.get_single_value("System Settings", "enable_scheduler")
  File "/Users/shahin/frappe-demo/apps/frappe/frappe/database/database.py", line 884, in get_single_value
    ).run()
      ^^^^^
  File "/Users/shahin/frappe-demo/apps/frappe/frappe/query_builder/utils.py", line 85, in execute_query
    result = frappe.db.sql(query, params, *args, **kwargs)  # nosemgrep
             ^^^^^^^^^^^^^^^^^^^^^^^^^^^^^^^^^^^^^^^^^^^^^
  File "/Users/shahin/frappe-demo/apps/frappe/frappe/database/database.py", line 237, in sql
    self.connect()
  File "/Users/shahin/frappe-demo/apps/frappe/frappe/database/database.py", line 135, in connect
    self.get_connection()
  File "/Users/shahin/frappe-demo/apps/frappe/frappe/database/mariadb/database.py", line 106, in get_connection
    conn = self._get_connection()
           ^^^^^^^^^^^^^^^^^^^^^^
  File "/Users/shahin/frappe-demo/apps/frappe/frappe/database/mariadb/database.py", line 112, in _get_connection
    return self.create_connection()
           ^^^^^^^^^^^^^^^^^^^^^^^^
  File "/Users/shahin/frappe-demo/apps/frappe/frappe/database/mariadb/database.py", line 115, in create_connection
    return pymysql.connect(**self.get_connection_settings())
           ^^^^^^^^^^^^^^^^^^^^^^^^^^^^^^^^^^^^^^^^^^^^^^^^^
  File "/Users/shahin/frappe-demo/env/lib/python3.11/site-packages/pymysql/connections.py", line 361, in __init__
    self.connect()
  File "/Users/shahin/frappe-demo/env/lib/python3.11/site-packages/pymysql/connections.py", line 669, in connect
    self._request_authentication()
  File "/Users/shahin/frappe-demo/env/lib/python3.11/site-packages/pymysql/connections.py", line 957, in _request_authentication
    auth_packet = self._read_packet()
                  ^^^^^^^^^^^^^^^^^^^
  File "/Users/shahin/frappe-demo/env/lib/python3.11/site-packages/pymysql/connections.py", line 775, in _read_packet
    packet.raise_for_error()
  File "/Users/shahin/frappe-demo/env/lib/python3.11/site-packages/pymysql/protocol.py", line 219, in raise_for_error
    err.raise_mysql_exception(self._data)
  File "/Users/shahin/frappe-demo/env/lib/python3.11/site-packages/pymysql/err.py", line 150, in raise_mysql_exception
    raise errorclass(errno, errval)
pymysql.err.OperationalError: (1045, "Access denied for user '_1fb2a6bb76c4b738'@'localhost' (using password: YES)")
